Workbook

Sheet ПЛАН
A1: Ноябрь 2024 | E1: Декабрь 2024 | I1: Январь 2025 | L1: Февраль 2025 | P1: МАРТ 2025 | T1: АПРЕЛЬ 2025 | X1: 45778 | AB1: Июня 2025 | AF1: Август 2025 | AJ1: Сентябрь 2025 | AN1: Октябрь 2025 | AR1: Ноябрь 2025 | AV1: Декабрь, 2025 | AZ1: ФЕВРАЛЬ 2026 | BD1: МАРТ 2026 | BH1: АПРЕЛЬ 2026 | BL1: МАЙ 2026 | BP1: ИЮНЬ 2026 | BT1: ИЮЛЬ 2026
A2: 28.10-03.11 | B2: 04.11-10.11 | C2: 11.11-17.11 | D2: 18.11-24.11 | E2: 25.11-01.12 | F2: 02.12-08.12 | G2: 09.12-15.12 | H2: 16.12-24.12 | I2: 25.12-12.01 | J2: 13.01-19.01 | K2: 20.01-24.01 | L2: 25.12-02.02 | M2: 03.02-09.02 | N2: 10.02-16.02 | O2: 17.02-24.02 | P2: 25.02-02.03 | Q2: 03.03-09.03 | R2: 10.03-16.03 | S2: 17.03-24.03 | T2: 25.03-30.03 | U2: 31.03-06.04 | V2: 07.04-13.04 | W2: 14.04-24.04 | X2: 25.04-04.05 | Y2: 05.05-11.05 | Z2: 12.05-18.05 | AA2: 19.05-24.05 | AB2: 25.05-01.06 | AC2: 02.06-08.06 | AD2: 09.06-15.06 | AE2: 16.06-24.06 | AF2: 25.07-03.08 | AG2: 04.08-10.08 | AH2: 11.08-17.08 | AI2: 18.08-24.08 | AJ2: 25.08-31.08 | AK2: 01.09-07.09 | AL2: 08.09-14.09 | AM2: 15.09-24.09 | AN2: 25.09-05.10 | AO2: 06.10-12.10 | AP2: 13.10-19.10 | AQ2: 20.10-24.10 | AR2: 25.10-02.11 | AS2: 03.11-09.11 | AT2: 10.11-16.11 | AU2: 17.11-24.11 | AV2: 25.11-30.11 | AW2: 01.12-07.12 | AX2: 08.12-14.12 | AY2: 15.12-24.12 | AZ2: 25.01-01.02 | BA2: 02.02-08.02 | BB2: 09.02-15.02 | BC2: 16.02-24.02 | BD2: 25.02-01.03 | BE2: 02.03-08.03 | BF2: 09.03-15.03 | BG2: 16.03-24.03 | BH2: 25.03-05.04 | BI2: 06.04-12.04 | BJ2: 13.04-19.04 | BK2: 20.04-24.04 | BL2: 25.04-03.05 | BM2: 04.05-10.05 | BN2: 11.05-17.05 | BO2: 18.05-24.05 | BP2: 25.05-31.05 | BQ2: 01.06-07.06 | BR2: 08.06-14.06 | BS2: 15.06-24.06 | BT2: 25.06-05.07 | BU2: 06.07-12.07 | BV2: 13.07-19.07 | BW2: 20.07-24.07
A3: Направлен ежемесячный отчёт ФГИСКИ | B3: Подготовлен приказ и актуализированы (23 документа) ОРД в соответствии с резолюцией. | C3: Настроено ЕОП: Аппарат. Найдена уязвимость по информационной безопасности. | E3: Заключено дополнительное соглашение на аренду аппаратных мощностоей (до 2025 года) | G3: Направлен отчёт ПИ24 | I3: Проведена работа по развёртыванию новых 4 серверов (ИИ, Бот, Сервер баз данны, сервер приложений), заключено дополнительное соглашение | K3: Подготовлено ТЗ на реализацию функционала отправки электронной отчётности | L3: Выполнена подготовка к переносу баз данных по ЗП учреждений здравоохранения. Разделение едниной базы на множество по учреждениям | N3: Проведён анализ формирования пакетов с типом «Отчет об имуществе» в Государственных учреждениях для дальнейшей отправки в ГИС Имущество. Консультации в исправлении ошибок учета ОС и помощь в написании заявок в Фаргус и НПО Криста. Тестовая выгрузка совместно с сотрудниками Департамента Имущества | O3: Перенос остатков ЯМАЛСПАС на 01.01.2025, при смене формы организации юридического лица | P3: Выполнено тестирование Личного кабинета в части подписания документов 61н КЭП | Q3: Проведено ВКС на тему реинжиниринга аппаратных мощностей, обеспечивающие серверные функции ГИС "Смета ЯНАО" | R3: Настроено Единое окно подписания на 29 БД | S3: Внесены изменения в план информатизации: добавлено 2 мероприятия, разработана схема взаимодействия в нотации bpm, изменены 2 мероприятия (увеличены суммы и количество организаций) | T3: Успешно апробирован плагин подписания документов (КЭП) в Веб-Смете. Соблюдена полная совместимость плагина Веб-Сметы и ЛК. Теперь есть поддержка для РЕД ОС 8 | U3: Выполнены настройки по новым документам в ГИС "СМЕТА ЯНАО": Инвентаризация БСО, Карточка справка электронное подписание | V3: Выполнена настройка 25 баз данных для согласования уведомлений МБТ от МО к ОУи ЦБ | W3: Выполнена настройка с МЧД для отправки отчётности с федеральную налоговую службу. Проведена работа с ИО по получению открытых ключей КЭП, диагностике ошибок канала связи: Смета-Астрал-ФНС | X3: Направлен отчёт "Затраты на ПО и меры поддержки IT-проектов" | Z3: Сформирован и направлен реестр данных по импортозамещению | AA3: Актуализировано ТЗ на сопровождение ГИС "Смета ЯНАО" | AB3: Подготовлено ТЗ на выполнение работ по развитию ГИС «Смета ЯНАО» в части обеспечения электронного взаимодействия с внешней информационной системой ГИС «Имущество ЯНАО» | AC3: Подготвлена 1-я редакция техтребований на выполнение работ по разивитию ГИС "Смета ЯНАО" в части администрирования (Принцип nsi.yanao.ru) | AD3: Подготовлено финансово-экомические обоснования: Интеграция с ТЕЗИС, ЕСКУ, Сопровождение ГИС "Смета ЯНАО" в 2026 | AE3: Подготовлен перечень функционала для делегирования и перераспределения сотрудников отдела IT в случае отвлечений | AF3: Подготовлено ТЗ на выполнение работ по развитию ГИС «Смета ЯНАО» в части обеспечения электронного взаимодействия с внешней информационной системой ГИС «Имущество ЯНАО» | AG3: Подготвлена 1-я редакция техтребований на выполнение работ по разивитию ГИС "Смета ЯНАО" в части администрирования (Принцип nsi.yanao.ru) | AH3: Подготовлено финансово-экомические обоснования: Интеграция с ТЕЗИС, ЕСКУ, Сопровождение ГИС "Смета ЯНАО" в 2026 | AI3: Подготовлен перечень функционала для делегирования и перераспределения сотрудников отдела IT в случае отвлечений | AJ3: Направлен отчёт "Затраты на ПО и меры поддержки IT-проектов" | AK3: Подготовлены бизнес-требования интеграции ЛКиЛКггс | AL3: Разработан сервис для получения в реальном времени количественных показателей - обработанных файлов - вложлений подотчётных первичных документов искусственным интеллектом. Итерация 1 | AM3: Подготовлено ТЗ Кросс-подписание | AN3: Направлен отчёт "Затраты на ПО и меры поддержки IT-проектов" | AO3: ЛК: обновлён интерфейс, автоматическое распознавание по умолчанию, автоматическая классификация, добавлена возможность распознавания проездных документов по транспорту (вертолет, автобус, дополнительные виды жд билетов), добавлен форматно-логический контроль заполнения формы | AP3: Утверждён план работ по развитию Сметы в части администрирования. Проводится работа по подготовке MVP на примере выборочный БД | AQ3: Проведена коррекция плана информатизации 2025 | AT3: Проведено тестирование Веб-Смета 2.0. Подготовлен список замечаний (28) | AU3: Разработана концепция единого сервера обновлений Сметы для всех участников бюджетного процесса (стабильная ветка), экспериментальная ветка обновлений (ЦБ). Практическое применение после обновления ЭДО и тестирования. В РЕЗУЛЬТАТЕ: для любого подключения из РМТКС - ЕДИНЫЙ СЕРВЕР ОБНОВЛЕНИЙ СМЕТЫ, как стабильной ветки, так и экспериментальной | AZ3: сервис telemost.yanao.ru теперь доступен везде где установлена Смета, направлено письмо для популяризации сервиса в исполнительные органы в ЯНАО | BA3: Разработано ТЗ по получению справок об обучении через витрину данных Образования (СМЭВ), проработаны вопросы и учтены предложения Исполнителя | BB3: Подготовлен проект ТЗ на слияние баз данных ГИС "Смета ЯНАО" отдельных муниципальных учреждений | BC3: ЕСИА выполнены запросы КП на пусконаладочные работы программного модуля НТЦК для интеграции с ФГИС ЕСИА, найдено как минимум одно рабочее решение. Работа продолжается | BD3: Проведены исследования по автоматическому подписанию квалифицированной электронной подписью на стороннем сервисе любых документов. Модель соответствует требованиям по информационной безопасности, возможна реализация собственными силами учреждения | BG3: Развёрнут тестовый контур интеграции Смета-Тезис. Успешно выполнено подключение между серверами, реализована модель аутентификации | BH3: Подготовлен чек-лист сопровождения работы сервиса подотчётных лиц | BI3: Подготовлена информация по муниципальным образованиям в ЯНАО в части детализации отображения сведений по заработной плате руководителей на fa.yanao.ru | BJ3: Проведена приёмка функционала самоадминистрирования баз данных ГИС "Смета ЯНАО" на примере тестовой базы и исключительно в тонком клиенте. Замечаний не зафиксировано | BK3: Сформулированы функциональные требования и разработана архитектура будущего приложения с связке с SDK "Адаптер Инфраструктуры" для интеграции сервиса подотчётных лиц с ФГИС ЕСИА. Проведено установочное совещание на котором распределены роли и задачи для НПО Криста и Ставеру А.П. | BL3: Направлен отчёт: ФГИСКИ | BM3: ЕСИА: Развёрнут контур подключения на рабочих серверах, передано управление НПО "Криста" для интеграции ЛК | BP3: Актуализировано ТЗ по мероприятию: Оказание услуг по настройке ГИС «Смета ЯНАО» в части электронного взаимодействия (интеграции) с внешней информационной системой ГИС «Имущество ЯНАО» | BQ3: Направлен отчёт: ФГИСКИ | BS3: Направленная ранее заявка в Федеральный институт промышленной собственности успешно отработана; проводится работа по корректировке(совместно А.А. Черновым) | BT3: Отправлен отчёт по ЕСКУ | BU3: ЕСИА: Реализовать функционал репликаций учётных записей в сводную БД по СНИЛС в двух режимах: планировщик, в ручном режиме
A4: Добавлен функционал ЕОП для руководителей структурных подразделений (Дитис БД) | B4: Исправлены ошибки и протестирован импорт документов из ЕИС | C4: Разработан чат-бот. Функционал: загрузка баз данных новых участников бухгалтерского бюджетного процесса, ознакомление с информацией для новых пользователей Сметы, выполнена работа по развёртыванию как модуль ГИС Смета ЯНАО. Подробнее: Rev01: > подключено СУБД (couchdb) > фиксируются новые пользователи при старте бота с унифицированной структурой, (т.е. новые пользователи могут менять роли) > добавлен интерфейс мандатных-пользователей > добавлен интерфейс Техподдержки > реализован обмен файлами > реализован функционал скрытия меню, обновления диалогов (MessageCleaner) > реализованы методы создания и обновления документов в БД > реализованы сценарии для пользователей групп: admin, users, mandatory, fargos > реализована точка входа для интеграции с ИИ (endpoint): чтение чатов и реагирование на сообщения > контейнеризация баз данных (docker) > FAQ > функционал для обновления бота | K4: разработан интерфейс для создания новых мандатных пользователей для тер.менеджеров (чат-бот) | M4: Выполнено тестирование функционала обмена ГИС Смета и ГИС Имущество с разнями типами пакетов | N4: Консультация пользователей ГИС Смета по работе функционала обмена данными с ГИС Имущество | O4: Разрабатываем единый механизм учета "Аренда жилищного фонда" для муниципалитетов, начали отрабатывать данный механизм на базе МКУ "Городской центр имущественных и жилищных отношений". Ведутся работы по переносу остатков из разных программных продуктов (Смета и 1С БГУ, ГИС Жилфонд, Excel). | P4: Уведомления: разработан протокол описание уведомлений по 30 документам | Q4: Направлен отчёт "Импортонезависимое ПО" | R4: Настроено ЕОП на базах данных субъектов централизованного учёта | S4: Направлен и принят отчёт 3-информ РОССТАТ | T4: Успешно внедрён ЛК+ИИ с конфигураций синхронных запросов, распознавания на отчётах о расходах и модальным окном для опционального распознавания | U4: Проведен ВКС: внедрение уведомлений субъектами нецентрализованного учёта | V4: Выполнены настройки по новому документу в ГИС "СМЕТА ЯНАО": Исходящий счет бух.справка | X4: Подготовлены технические требования на реализацию функционала работы с документами между участниками разных баз данных Сметы | Z4: Подготовлено ТЗ на интеграцию с ГИС Имущество | AB4: Направлен отчёт "Затраты на ПО и меры поддержки IT-проектов" | AC4: Направлена первая редакция предварительного плана информатизации 2026, утверждено, включены мероприятия: Госфинансы, Росдормониторинг, Сопровождение, Интеграция с ГИС АПК | AD4: Подготвлена 1-я редакция техтребований на выполнение работ по разивитию ГИС "Смета ЯНАО" в части кросс-подписания электронных документов между пользователями разных баз данных | AF4: Направлен отчёт "Затраты на ПО и меры поддержки IT-проектов" | AG4: Направлена первая редакция предварительного плана информатизации 2026, утверждено, включены мероприятия: Госфинансы, Росдормониторинг, Сопровождение, Интеграция с ГИС АПК | AH4: Подготвлена 1-я редакция техтребований на выполнение работ по разивитию ГИС "Смета ЯНАО" в части кросс-подписания электронных документов между пользователями разных баз данных | AJ4: Направлено письмо в ДИТИС О рассмотрении вопроса о закупке программно-аппаратного комплекса для интеграции с ЕСИА | AK4: Выполнена приёмка ГК: ППО | AL4: Выполнена приёмка ГК: Наградной отдел | AM4: Подготовлено ТЗ "Специфика хозопераций МУ-учреждений" | AN4: Подготовлено ТЗ на оказание услуг по настройке функционала ГИС «Смета ЯНАО» под специфику хоз. операций МУ | AP4: Разработан типовой шаблон ТЗ | AQ4: Проведена совместная с ГКУ "Ресурсы Ямала" работа по переходу на использование Smeta-координатора ViPNet для устранения ошибок подключения удалённых пользователей | AT4: Подготовлено ТЗ для интеграции с ГИС Образования Ямала через витрину данных Образования для получения справок об обучении школьников (для льготного отпуска). | AU4: Подготовлена служебная записка о вводе в эксплуатацию программного обеспечения для удалённого доступа | AV4: Подготовлен Dashboard на основе BI-данных | AZ4: Направлен отчёт: Затраты на ПО и меры поддержки ИТ-проектов | BA4: Проработаны вопросы и учтены предложения Исполнителя по ТЗ Росдормониторинг | BB4: Подготовлены предложения по внедрению новых прикладных сервисов, основанных на использовании массивов больших данных | BC4: Выполнена работа по поиску и устранению причин неработоспособности ЛК-сервиса в связке с модулем ИИ и системой мониторинга процессов. Добавлен функционал превентивного мониторинга посредством оповещения в чат-бот о проблемах с сервисами | BD4: Сформирован и направлен отчет 3-информ | BE4: Подготовлено письмо в депфин о содействии в присоединении к личному кабинету участника взаимодействия департамента финансов | BF4: Подготовлено ТЗ по слиянию баз данных | BG4: Разработана схема интеграции по направлению Смета-АПК в части подписания всех запросов квалифицированной электронной подписью | BH4: Направлен отчёт: затраты на ПО и меры поддержки ИТ проектов | BJ4: Проведена работа по поиску и устранению ошибок сервиса telemost.yanao.ru. Работа сервиса восстановлена после изменения IP и включения паравиртуализации | BK4: Проработана схема интеграции ГИС РЭБ ЯНАО (Исполнение) с ГИС "Смета ЯНАО" в части заявок на межбюджетный трансферт | BL4: Направлен отчёт: затраты на ПО и меры поддержки ИТ проектов | BM4: Подготовлена расширенная модель интеграции ГИС "РЭБ ЯНАО" и ГИС "Смета ЯНАО" в части межбюджетных трансфертов | BP4: Направлен отчёт: затраты на ПО и меры поддержки ИТ проектов | BS4: Выполнены тестовые испытия промышленной ЕСИА, модифицирован код API-серверов, добавлены сертификаты удостостоверяющих центров | BT4: ЕСИА: Выполнено кэширование закрытого ключа в КриптоПро | BU4: ЕСИА: Выполнен контрольный тест сценариев ЛК: 1. Регистрация и авторизация не имеет значения, пользьзователь просто входит если есть права доступа на БД. 2. Обработка ислючительных ситуаций: Если пользователя нет ни в одной БД по СНИЛС, то сообщение об ошибке; Если пользователь найден в одной организации - автоматический вход; Если пользователь найден в нескольких организациях - выбор организации для входа | BW4: ЕСИА: Модифицирован метод logout для отзыва сессии ЕСИА
A5: Направлен ежемесячный отчёт (Импортозамещение) | B5: Исправлены ошибки и протестирован импорт документов из РКС. На тестовой базе пока – у Якуты на проверке в части корректного отражения счетов | C5: Выполнена работа по анализу архитектуры защищённой сети в связи с поступающими сигналами: 1. Регулярная потеря связи у разработчика (Техфаргос) 2. Предстоящее экстенсивное программное порабощение 800+ учреждений в 25-26 годах. Данные рекомендации (1), сделать доступ к серверу приложений по TLS (2). Кроме этого, при новой схеме требуется переработать способ удалённого подключения разработчика к пользователям Сметы | D5: Проведена совместная работа отделом аудита по разработке новой версии положения о ГИС Смета ЯНАО | E5: Выполнена приёмка ГК на развитие ЛК | G5: Опытная эксплуатация нового функцоинала ЛК на БД ЦБ: работа над ошибками | I5: Проведена работа по поиску и устранению инцидентов доступности сервера авторизации ГИС Смета ЯНАО: найден конфликт сетевых адресов, исправлен способ взаимодействия узла Сметы и координаторов новых участников | J5: Проведено тестирование чат-бота (версия 1.2) | K5: Проведена работа по тестированию ИИ в smeta.yanao.ru: найдены ошибки устраняются в настоящее время, срок - орфографические ошибки распознавания (если среднее качество ближе к 200dpi) - логические ошибки, связанные с датами - проблема связанная со с несколькими маршрутами в одной м. квитанции 2. 2. | M5: Департамент соцзащиты: Обнуление остатков на 01.01.2025 г. Консультации по внесению корректных остатков на 01.01.2025 г. и дальнейшей работы с ГИС Смета | P5: Уведомления – выполнена настройка и тестирование уведомлений для проездных документов, для 28 баз ИО. Частично выполнена настройка и тестирование уведомлений по документам 61н. Подготовлена инструкця по добавлению чат бота для уведомлений. | R5: Настроена видимость по выплатам на карты МИР на базах данных субъектов централизованного учёта | S5: Обновлено хост-приложение и интерфейс для подписания КЭП в ЛК, а также функционал дорожной карты бизнес-процессов | T5: Реализован функционал "права настройщика". Функционал позволяет наиболее гибко и оперативно отлаживать настройки документооборота | U5: Настроены уведомления по 10 документам 61н на 29 бд | V5: Подготовлена инструкция для специалистов учреждений МО и ОУ по созданию и отправке Уведомлений МБТ разослана сотрудникам отдела Поставщиков | X5: Подготовлено ТЗ на прямые выплаты | Z5: Подготовлены технические требования на реализацию функционала самоадминистрирования участниками Сметы | AB5: Разработана архитектура приложения для удалённого доступа. Подключена база данных, функционирует REST API-сервис для авторизации, подтвеждения одноразового кода. отправленного на email (@yanao.ru), функция создания виртуальных машин с установленными параметрами (на базе РЕД ОС), пробросами портов (на базе noVNC) | AF5: Разработана архитектура приложения для удалённого доступа. Подключена база данных, функционирует REST API-сервис для авторизации, подтвеждения одноразового кода. отправленного на email (@yanao.ru), функция создания виртуальных машин с установленными параметрами (на базе РЕД ОС), пробросами портов (на базе noVNC) | AJ5: Разработана приложения для удалённого доступа. Завершение работы над минимально-жизнеспособным продуктом (MVP) | AO5: Приложение для удаленного доступа развернуто В РМТКС ЯНАО по доменному имени. Соблдены требования информационной безопасности (внешние). Запущена тестовая эксплуатация | AU5: Внесены изменения в план информатизации 2025 | AX5: telemost.yanao.ru: доступ предоставлен для НПО Криста | AZ5: Выполнил подготовку документов в Роспатент | BB5: Разработан скрипт отчёта включения/выключения рабочих мест | BC5: Устранены ошибки в ЛК-сервисе в части умного распознавания электронных документов | BE5: Подготовлен вариант регламента взаимодействия участников (из числа МО, МКУ, ГКУ) в рамках оказания технической поддержки | BF5: Подготовлен свод замечаний по удобству пользвания UX ЛК | BG5: Проведены работы по обновлению сервера telemost.yanao.ru. Продолжается работа по устранению последствий | BK5: Сформулированы и направлены функциональные требования для изменения способа взаимодействия клиентов и серверов приложений в рамках развития технологии TLS Gateway относительно ГИС "Смета ЯНАО" | BL5: Устранение уязвимостей серверного вспомогательного программного обеспечения ВМ OPT | BP5: Направлена заявка на промышленную ЕСИА; совместно с отделом информационной безопасности проведена работа по взаимодействию с НИИ "Восход" и Ростелеком | BQ5: Проведена работа по обновлению схемы топологии ЯНАО: уточнялись каналы взаимодействия, маршруты прохождения данных, состав систем и сервисов. Результатом стала обновлённая актуализированная схема с учетом текущей архитектуры и взаимодействующих контуров. | BR5: Проведена работа по актуализации таблиц Excel с выборками органов и учреждений по направлению ЕСКУ. Проведена сверка списков, выявлены отсутствующие, новые и дублирующиеся записи. В результате был подготовлен максимально актуальный список учреждений для дальнейшей работы и сопоставления данных | BS5: Проведено зондирование вопроса подключения уведомлений в чат-бот "Бухагалтер Света" (Среда) от функционала ЭДО "Отчётность" (Астрал). Выявлены ключевые точки роста, оценена рентабельность мероприятия (Не рентабельно) | BT5: ЕСИА: Разработаны синтетические тесты для определения пределов нагрузки сервиса авторизации при использовании в ЛК с целью предиктивного наращивания | BV5: ЕСИА: Выполнено централизованное сканирование на уязвимости серверного программного обеспечения узлов: Surgate-шлюз, сервер ЛК, ЕСИА-Адаптер | BW5: ЕСИА: уязвимости устранены
A6: Направлено письмо в Минцифры России с запросом о ходе исполнения заявки | B6: Выполнена настройка по всем базам нового типа документа – Закрытие периода | C6: Выявлены условия и определён способ интеграции Смета-ЕСИА. Требуется включить в ПИ25 и бюджетную смету закупку лицензий на ПО КриптоПро | D6: Направлены изменения ППИ25 (СКЗИ для ЕСИА). Изменения приняты | E6: Участие в ВКС по РИС:Информатизация | G6: Проведена работа по устранению последствий повреждения баз данных | J6: Актуализирована структура, информация по сотрудникам и размещена инструкция на сайте учреждения согласно новому штатному расписанию. | K6: Проведена подготовка к переносу баз данных по ЗП учреждений здравоохранения. Разделение едниной базы на множество по учреждениям | P6: Подготовлена диаграмма по исполнительской дисциплине (февраль 2025, год 2024) улучшена диаграмма по звонкам (февраль 2025). В работе заявки по корректировке отчета «Нагрузка бухгалтера» | Q6: Донастроен запрос безвозмездной передачи от одного балансодержателю к другому из потребности учреждений (ГКУ) | R6: Проведно успешное тестирование подписания и отправки в одном платёжном поручении множественной детализации | S6: произведена замена пары открытого-закрытого ключа обезличенный КЭП на сервере ADGATE "Администрирование доходов" | T6: Анализ формирования пакетов с типом «Отчет об имуществе» в Государственных учреждениях для дальнейшей отправки в ГИС Имущество. Консультации в исправлении ошибок учета ОС и помощь в написании заявок в Фаргус и НПО Криста. Тестовая выгрузка совместно с сотрудниками Департамента Имущества | U6: Направлен отчёт: Затраты на ПО и меры поддержки ИТ-проектов | V6: Выполнена проверка работоспособности интеграции Сметы и РКС в части объектов малой закупки (до 600 тыс) | X6: Выполнены работы по апробации нового функционала отправки отчётности в федеральные органы. Опытным путём выявлены требования к КЭП, способах формирования МЧД и иных условиях, необходимых для корректного формирования исходящих пакетов данных. Проведена работа по созданию и портированию МЧД и учётных записей, сопровождению бизнес-процесса | AB6: Внедрён функционал распознавания электронных проездных документов на базе искусственного интеллекта. Распознаванию подлежат: авиа и жд-билеты, гостиницы. Выполнены предварительные нагрузочные испытания сервиса, подключена языковая модель, установленная и настроенная на базе ГКУ Ресурсы Ямала в виде GPU-мощностей, проведена работа по коммуникации с коллегами из ДИТИСа и ГКУ Ресурсы Ямала, устранены критические ошибки распознавания сервиса, проведён анализ удобства пользования (Usability), работы по повышению качества продолжаются. | AF6: Внедрён функционал распознавания электронных проездных документов на базе искусственного интеллекта. Распознаванию подлежат: авиа и жд-билеты, гостиницы. Выполнены предварительные нагрузочные испытания сервиса, подключена языковая модель, установленная и настроенная на базе ГКУ Ресурсы Ямала в виде GPU-мощностей, проведена работа по коммуникации с коллегами из ДИТИСа и ГКУ Ресурсы Ямала, устранены критические ошибки распознавания сервиса, проведён анализ удобства пользования (Usability), работы по повышению качества продолжаются. | AI6: Подготовлено и согласовано ТЗ на интеграцию с ЕСКУ | AM6: Разработана концепция по оценке качества работы ИИ, выраженной в виде бизнес-требований, а также форматах взаимодействия ИС (json) | AP6: Витрина данных. ГИС Образование со Сметой (получение справок об обучении): направлена заявка на присоединение к СМЭВ, разработана схема взаимодействия | AQ6: Развернут инструмент для применения новых концепций распознвания ИИ электронных документов. | AU6: Проведено обучение Техфаргас (telemost.yanao.ru) | AX6: telemost.yanao.ru исправлен функционал, многократно увеличено быстродействие | BE6: Собственными силами развёрнут стенд и программное обеспечение "Адаптер Инфраструктуры" для интеграции с ЕСИА.Провена проверка работоспособности всех модулей. Приступаем к тестирования непосредственно подключения к ЕСИА | BJ6: Подготовлено и согласовано ТЗ по интеграции ГИС "Смета ЯНАО" и РСЭД ЯНАО | BP6: Направлен и согласован предварительный проект плана информатизации 2027 | BQ6: Выполнена работа по развитию автоматизации бизнес-процесса межбюджетных трансфертов: Проведены переговоры, исследования, согласование новой схемы взаимодействия, найден консенсус, который не позволит вносить изменения в документ-основание (заявку на МБТ) в случае создания расчёта по нему. Также, подготовлена система статусов для Исполнения бюджета и обновлена BPMN-схема "как должно быть" | BR6: Выполнена работа по развитию автоматизации бизнес-процесса межбюджетных трансфертов: Подготовлена BPMN-схема "как есть сейчас", а также описан бизнес-процесс в деталях «как должно быть» на стороне ГИС "Смета ЯНАО". Подготовлены функциональные требования | BS6: Включен механизм журналирования входящих запросов для тела запроса с полезной нагрузкой - пользовательскими данными в рамках интеграции с АИС Жилфонд. Это позволит быстро обращаться к журналам отправленных в Смету данны ретроспективно для разрешения спорных ситуаций в рамках интеграции | BT6: Выполноно обновление промежуточного программного обеспечения Surgate для подключения к ЕСИА подсистемы формирования и обработки электронных документов (smeta.yanao.ru) | BU6: ЕСИА: синтетические тесты выполнены: сервис готов к эксплуатации - не менее Х пользователей одновременно | BW6: ВКС с Кристой по интеграции с Тезисом???
A7: Подготовлено ТЗ на двухэтапный ГК по развитию искусственного интеллекта | B7: Настроено во всех БД подписание бух. справок для документов: Поступление забаланс Выбытие НФА Поступление НФА Перемещение НФА Начисление амортизаций Переоценка НФА Модернизация НФА Выбытие забаланс Входящий счет | C7: Актуализированы должности сотрудников ЦБ в базах данных исполнительных органов (12) | D7: Актуализированы должности сотрудников ЦБ в базах данных исполнительных органов (16) | E7: Подготовлен и заполнен ПИ25 в новой ИС (РКС) | H7: Настроена и успешно протестирована на департаменте Госжизнадзора схема Уведомлений по МБТ от МУ к утверждению ОУ и принятию к учету ЦБ | J7: Проведно тестирование подключения к Смете через TLS-шлюз: найдены ошибки, возникающие теперь периодически. Анализ ошибки требует дополнительных инцидентов, соответствующая работа проводится по настоящее время | P7: Получены базы данных субъектов централизованного учёта здравоохранения ЯНАО: 16 баз данных бухгалтерий, 10 баз данных заработной платы. Проведены консультации с ключевыми сотрудниками здравоохранения ЯНАО (Дирекция) по выверке остатков после миграции данных. | U7: Произведена инсталляция ViPNet + dst на сервер интеграции с ЕСИА (smeta.yanao.ru) | V7: Отчёт по импортозамещению | X7: Проведена работа по актуализации ТЗ, направленного на автоматизацию наградного отдела аппарата Губернатора ЯНАО | AA7: Сформированы технические требования на реализацию интеграции ТЕЗИС и Сметы в 2026 году | AB7: Проведена работа по переформированию МЧД для ФНС функционала ГИС "Смета ЯНАО" "Внеший ЭДО" (Астрал) для своевременного и корректного получения уведомлений из налогового органа, подписано доверенностей - 24 из 27, в работе - 2 (ДИТИС, ГПД, ДГЗиПБ), работа продолжается; направлено письмо о новом функционале в исполительные органы, подготовлена памятка для работы пользователей; другие направления ЭДО (СФР, Росстат) включены и функционируют в штатном режиме, ошибки устраняются по факту их возникновения в ручном режиме | AF7: Проведена работа по переформированию МЧД для ФНС функционала ГИС "Смета ЯНАО" "Внеший ЭДО" (Астрал) для своевременного и корректного получения уведомлений из налогового органа, подписано доверенностей - 24 из 27, в работе - 2 (ДИТИС, ГПД, ДГЗиПБ), работа продолжается; направлено письмо о новом функционале в исполительные органы, подготовлена памятка для работы пользователей; другие направления ЭДО (СФР, Росстат) включены и функционируют в штатном режиме, ошибки устраняются по факту их возникновения в ручном режиме | AU7: Подготовлены схемы в нотации bpm для мероприятий по развитию ГИС Смета ЯНАО в 2026 году (ИнтТезис, Витрина образования, Росдормониторинг,Метрики, АПК) | BP7: Инвентаризированы оферты подключения к ГИС "Смета ЯНАО" муниципальных учреждений в ЯНАО, оферт собрано - 750 | BQ7: Подготовлено ТЗ по интеграции Смета+Тезис | BR7: Проведена работа по сбору актов должников по итеграции ГИС "Смета ЯНАО" и ГИС "ЕСКУ ЯНАО", собрано - Х ед | BT7: ЕСИА: Реализованы методы logout на уровне сессий приложения | BV7: ЕСИА: на уровне ЛК реализован метод logout, добавлен косметический-preloader | BW7: Предварительный план инфорпматизации размещен в системе rks.yanao.ru
D8: Проработан вопрос использования TLS Gateway в РМТКС по алгоритмам RSA/GOST3410. Требуется доработка клиентского ПО. Релиз запланирован на 05.12.24 | F8: Проведена работа по проектированию аппаратных мощностей на 2025-2026 годы для обеспечения работоспособности Сметы в условиях приращения числа пользователей + заключено соглашение | J8: Подготовлена видео-инструкция для подготовки архивов и их загрузки в чат-Бот, инструкция опубликована на сайте учреждения. | K8: Проведено тестирование нового функционала «Выгрузка имущества» с типом пакета «Передача имущества». Найдены ошибки. Направлены разработчику | U8: направлено в исполнительные органы письмо о настройке в базах всплывающих уведомлений | V8: Настроен ЭД Табель ежедневный на БД ЦБ ОГВ. Функционал масштабируем, передан в техподдержку для распространения на подключениях Здравоохранения | AB8: Разработан сервис аналитики для оценки эффективности работы с заявками, телефонных звонков | AE8: Сервис аналитики для оценки эффективности работы с заявками, телефонных звонков: применение ИИ для категоризирования данных; с помощью ИИ из всего валового объёма заявок с 01.01.2025 года выявлены ТОП-5 направлений: интеграции (25%), интерфейс(17%), доступ (14%), настройки (10%), нет нужного функционала (10%). По телефонным звонкам: самые длинные разговоры, наибольшее/наименьшее количество звонков, пропущенные и т.д. Более подробно: https://websmeta.yanao.ru/static. | AF8: Разработан сервис аналитики для оценки эффективности работы с заявками, телефонных звонков | AH8: Подготовлен сводный отчёт (срез) по каждому МО с указанием учреждений, перешедших, но не осуществляющих ведение учёта в ГИС Смета ЯНАО | AU8: Подготовлена типовая дорожная карта мероприятий по развитию ГИС "Смета ЯНАО" | BP8: Инвентаризированы оферты подключения к ГИС "Смета ЯНАО" государственных учреждений в ЯНАО: оферт в наличии 48, ожидаем - 8; нет оферт - 25 (Здрав), 9 (Ликвидировано учреждений). Всего изначально - 90 | BR8: Проведено обучения (3 дня) для бухгалтеров муниципальных учреждений в ЯНАО по направлению: создание, подписание и закрытие платёжных поручений в ГИС "Смета ЯНАО" | BT8: ЕСИА: выполнено бэкап-копирование шлюза Surgate (Моноблок)
D9: Проведен анализ и выявлен наилучший способ для удалённого доступа разработчика к пользователям Сметы (в условиях отказа от массового отказа от ViPNet Client в РМТКС) | F9: Направлен отчёт: импортозамещение A(ФГИСКИ) | H9: Направлен ежемесячный отчёт (Импортозамещение) | K9: Проведён анализ формирования пакетов с типом «Отчет об имуществе» в государственных учреждениях для дальнейшей отправки в ГИС Имущество. Найдены ошибки, направлены разработчику. | V9: Направлены изменения в ПИ25 в части мероприятий по информатизации: ППО, Миграция дополнительных баз данных учреждений (которые раньше были запланированы на 2026 год), Техподдержа дополнительных баз данных, реализация функционала под специфику хоз.операция некоторых муниципальных учреждений. Подготовлены финансово-экономические обоснования. Все изменения согласованы | AT9: Подготовлено ТЗ для интеграции с Росдормониторинг | BP9: Проведено обучение администраторов Сметы на тему настройки платёжных поручений в базах данных пользователей всех муниципальных учреждений в ЯНАО | BR9: Выполнен срез используемого функционала платёжных поручений в ГИС "Смета ЯНАО" из числа, прошедших обучение, с фокусом: платёжные поручения, прямые выплаты | BW9: ТЗ по интеграции Сметы и РСЭД Тезис иправлено с учетом замечаний ДИТиС и направленно на конкурсные закупки служебной запиской в РСЭД Тезис
D10: Участие в ВКС (Техподдержка) | E10: Направлен отчёт: затраты на ПО и меры поддержки ИТ-проектов | F10: Обновлены инструкции в базе знаний | H10: Внедрён в тестовую эксплуатацию механизм подключения к Смете без ViPNet Client через TLS Gateway в РМТКС по алгоритмам RSA/GOST3410. | K10: Сбор заявок (некорректности функционала версии клиента:linux64—7725.4-хх), регистрация в НПО Криста и отслеживание | T10: Консультации пользователей (Дирекция по финансированию и материально-техническому обеспечению учреждений в сфере здравоохранения) по работе в ГИС Смета, совместная работа с пользователями по выверке остатков, внесению документов в систему и т.п. | AV10: Проверены концепции (в рамкха OKR26) внедрения ИИ по направлениям: Справочники НФА, бот-консультант на базе ИИ | AZ10: Проверены концепции (в рамкха OKR26) внедрения ИИ по направлениям: Справочники НФА, бот-консультант на базе ИИ | BD10: Проверены концепции (в рамкха OKR26) внедрения ИИ по направлениям: Справочники НФА, бот-консультант на базе ИИ | BH10: Проверены концепции (в рамкха OKR26) внедрения ИИ по направлениям: Справочники НФА, бот-консультант на базе ИИ | BL10: Проверены концепции (в рамкха OKR26) внедрения ИИ по направлениям: Справочники НФА, бот-консультант на базе ИИ | BP10: Проведена работа по обновлению инструкции по применению электронных документов ОКУД 0510521 «Заявка-обоснование закупки товаров, работ, услуг малого объема через подотчетное лицо (ф. 0510521) | BQ10: Подготовлено и согласовано ТЗ: Интеграция АПК | BT10: ЕСИА: Выполнена инсталляция антивирусной защиты на шлюз Surgate, исключены ошибки, препятствующие работоспособности шлюза
D11: Проведен ВКС с департаментом агропромышленного комплекса ЯНАО по вопросам интеграции | F11: Выполнены работы по настройке индивидуального квотирования загружаемых файлов для разных типов (видов) документов. Сообщаю Вам о наличии технической возможности прикреплять файлы (вложения) большого размера. Индивидуальная настройка действует в отношении ОКУД: 0504833 (бух.справка), 0504512/517/520 (отчёт о расходах, РОКи) и распространена на все базы данных ГИС Смета ЯНАО. | H11: Проведена приёмка ГК: уведомления, ИИ | K11: Подготовка к переносу остатков ЯМАЛСПАС на 01.01.2025, при смене формы организации юридического лица | T11: Консультация пользователей ГИС Смета по работе функционала обмена данными с ГИС Имущество | BP11: Сформулированы требования и разработан отчёт использования функционала ГИС "Смета ЯНАО" в части работы с первичными платёжными документами. Отчёт отражает точки роста и акцентирует внимание на базах данных, в которые платёжные первичные документы импортируются из Исполненеия бюджета | BR11: Проведена актуализация доступов в ГБУ «Дирекция ООПТ ЯНАО», ГКУ «Служба по охране биоресурсов ЯНАО», ГУ «Леса Ямала», ГАУ «Центр изучения Арктики» | BT11: Направлен отчёт: затраты на ПО и меры поддержки ИТ проектов
BP12: Подготовлено и согласовано ТЗ по мероприятию: Оказание услуг по настройке в ГИС «Смета ЯНАО» функционала в части учета, начисления и расчетов по плате, которую родители (законные представители) ежемесячно платят дошкольной образовательной организации за присмотр и уход за ребёнком (далее – родительская плата), компенсационных выплат по родительской плате, а также учет расчетов по платным услугам образовательных учреждений | BS12: Проведены испатания ОКУД 0504805 (Извещение), функционал "Кросс-подписание" на примере: Департамента строительства и жилищной политики ЯНАО и дирекции капительного строительства и инвестиций ЯНАО

Sheet СВОДНЫЙ ОТЧЁТ
A1: СВОДНЫЙ ОТЧЁТ О ПРОДЕЛАННОЙ РАБОТЕ ЗА ИЮНЬ 2026
A2: Отдел сопровождения, развития информационных систем и технической поддержки государственных и муниципальных учреждений
A3: Ставер А.П. | B3: Сапогов М.Д. | C3: Обмолова В.В. | D3: Роганова А.А. | E3: Гасанов С.Н. | F3: Кошик В.Н. | G3: Худышкин С.Н. | H3: Мулявин Я.В.
A4: =ПЛАН!BP4 -> Направлен отчёт: затраты на ПО и меры поддержки ИТ проектов | B4: =ПЛАН!BP10 -> Проведена работа по обновлению инструкции по применению электронных документов ОКУД 0510521 «Заявка-обоснование закупки товаров, работ, услуг малого объема через подотчетное лицо (ф. 0510521) | C4: =#REF! -> #REF! | D4: =#REF! -> #REF! | E4: =ПЛАН!BP8 -> Инвентаризированы оферты подключения к ГИС "Смета ЯНАО" государственных учреждений в ЯНАО: оферт в наличии 48, ожидаем - 8; нет оферт - 25 (Здрав), 9 (Ликвидировано учреждений). Всего изначально - 90 | H4: =ПЛАН!BQ5 -> Проведена работа по обновлению схемы топологии ЯНАО: уточнялись каналы взаимодействия, маршруты прохождения данных, состав систем и сервисов. Результатом стала обновлённая актуализированная схема с учетом текущей архитектуры и взаимодействующих контуров.
A5: =ПЛАН!BP5 -> Направлена заявка на промышленную ЕСИА; совместно с отделом информационной безопасности проведена работа по взаимодействию с НИИ "Восход" и Ростелеком | B5: =ПЛАН!BP12 -> Подготовлено и согласовано ТЗ по мероприятию: Оказание услуг по настройке в ГИС «Смета ЯНАО» функционала в части учета, начисления и расчетов по плате, которую родители (законные представители) ежемесячно платят дошкольной образовательной организации за присмотр и уход за ребёнком (далее – родительская плата), компенсационных выплат по родительской плате, а также учет расчетов по платным услугам образовательных учреждений | E5: =ПЛАН!BP9 -> Проведено обучение администраторов Сметы на тему настройки платёжных поручений в базах данных пользователей всех муниципальных учреждений в ЯНАО
D6: =#REF! -> #REF! | E6: =ПЛАН!BR8 -> Проведено обучения (3 дня) для бухгалтеров муниципальных учреждений в ЯНАО по направлению: создание, подписание и закрытие платёжных поручений в ГИС "Смета ЯНАО" | H6: =ПЛАН!BR5 -> Проведена работа по актуализации таблиц Excel с выборками органов и учреждений по направлению ЕСКУ. Проведена сверка списков, выявлены отсутствующие, новые и дублирующиеся записи. В результате был подготовлен максимально актуальный список учреждений для дальнейшей работы и сопоставления данных
A7: =ПЛАН!BP6 -> Направлен и согласован предварительный проект плана информатизации 2027 | E7: =ПЛАН!BR9 -> Выполнен срез используемого функционала платёжных поручений в ГИС "Смета ЯНАО" из числа, прошедших обучение, с фокусом: платёжные поручения, прямые выплаты
A8: =ПЛАН!BP11 -> Сформулированы требования и разработан отчёт использования функционала ГИС "Смета ЯНАО" в части работы с первичными платёжными документами. Отчёт отражает точки роста и акцентирует внимание на базах данных, в которые платёжные первичные документы импортируются из Исполненеия бюджета | E8: =ПЛАН!BR7 -> Проведена работа по сбору актов должников по итеграции ГИС "Смета ЯНАО" и ГИС "ЕСКУ ЯНАО", собрано - Х ед | F8: =ПЛАН!BR11 -> Проведена актуализация доступов в ГБУ «Дирекция ООПТ ЯНАО», ГКУ «Служба по охране биоресурсов ЯНАО», ГУ «Леса Ямала», ГАУ «Центр изучения Арктики» | G8: ='Количественная аналитика'!B41 -> Предоставление доступа сотрудника ОУ - 3 приказа; Устранение проблемы с созданием МЧД; Работа по внедрению подписания ф.0510448 и 0504805 между базами и устранение ошибок;
B9: =ПЛАН!BP3 -> Актуализировано ТЗ по мероприятию: Оказание услуг по настройке ГИС «Смета ЯНАО» в части электронного взаимодействия (интеграции) с внешней информационной системой ГИС «Имущество ЯНАО» | F9: ='Количественная аналитика'!B39 -> Сбор статистики по муниципалитетам - использования интеграции по направлениям: МИР, ПП, ЭДО, СФР, Имущество и т.п. | H9: =ПЛАН!BR6 -> Выполнена работа по развитию автоматизации бизнес-процесса межбюджетных трансфертов: Подготовлена BPMN-схема "как есть сейчас", а также описан бизнес-процесс в деталях «как должно быть» на стороне ГИС "Смета ЯНАО". Подготовлены функциональные требования
A10: =ПЛАН!BQ3 -> Направлен отчёт: ФГИСКИ | B10: ='Количественная аналитика'!K38 -> 0
A11: =ПЛАН!BQ6 -> Выполнена работа по развитию автоматизации бизнес-процесса межбюджетных трансфертов: Проведены переговоры, исследования, согласование новой схемы взаимодействия, найден консенсус, который не позволит вносить изменения в документ-основание (заявку на МБТ) в случае создания расчёта по нему. Также, подготовлена система статусов для Исполнения бюджета и обновлена BPMN-схема "как должно быть" | B11: ='Количественная аналитика'!B38 -> 1. Проводилась подготовка ТЗ на выполнение работ по интеграции с РСЭД Тезис 2. Организация и взаимодействие с участниками и техподдержкой по настройке и тестировании кроссподписания. 3. Проверка мероприятий предварительных ПИ на 2027 год среди МО и департамента здравоохранения. 4. Проводилась работа по администрированию, настройке прав, технической поддержке и решения иных вопросов на период отсутствия Чечеткина М.И., Обмоловой В.В. Рогановой А.И. 5. Подготовлены критерии для отчета по отслеживанию динамики авторизации через ЕСИА, сформулированы требования для отчета по командировкам и отпускам (заявки), решены несколько вопросов по ошибкам при импорте данных УКТ-Услуга, направлен отзыв заявки на регистрацию программы для ЭВМ (ИИ) чтобы повторно не платить пошлину. 6. Направлены ежемесячные отчеты по аудиту ПО и импортзамещению в ДИТиС (через депфин)
A12: =ПЛАН!BQ7 -> Подготовлено ТЗ по интеграции Смета+Тезис | B12: Актуализировано и направлено на согласование ТЗ на выполнение работ по интеграции с РСЭД Тезис с учетом замечаний от ДИТиС.
A13: =ПЛАН!BQ10 -> Подготовлено и согласовано ТЗ: Интеграция АПК
A14: =ПЛАН!BS3 -> Направленная ранее заявка в Федеральный институт промышленной собственности успешно отработана; проводится работа по корректировке(совместно А.А. Черновым) | B14: Работа по размещению предварительного ПИ на 2027 год
A15: =ПЛАН!BS4 -> Выполнены тестовые испытия промышленной ЕСИА, модифицирован код API-серверов, добавлены сертификаты удостостоверяющих центров | B15: Работа по акутализаци заявки на получение прав на ИИ
A16: =ПЛАН!BS6 -> Включен механизм журналирования входящих запросов для тела запроса с полезной нагрузкой - пользовательскими данными в рамках интеграции с АИС Жилфонд. Это позволит быстро обращаться к журналам отправленных в Смету данны ретроспективно для разрешения спорных ситуаций в рамках интеграции
A17: =#REF! -> #REF!
A18: =#REF! -> #REF!
A19: =ПЛАН!BS5 -> Проведено зондирование вопроса подключения уведомлений в чат-бот "Бухагалтер Света" (Среда) от функционала ЭДО "Отчётность" (Астрал). Выявлены ключевые точки роста, оценена рентабельность мероприятия (Не рентабельно)

Sheet Количественная аналитика
A1: Аналитическая информация по телефонным консультациям, отдел СРТП
A2: Месяц | B2: Количество звонков, отдел (входящие и исходящие) | C2: Ставер | D2: Сапогов | E2: Чечеткин | F2: Роганова | G2: Обмолова | H2: Кошик | I2: Гасанов | J2: Мулявин | K2: Худышкин
A3: октябрь 2023 | B3: =SUM(C3:G3) -> 2336 | C3: 342 | D3: 1320 | E3: 165 | F3: 374 | G3: 135
A4: декабрь 2023 | B4: =SUM(C4:G4) -> 3616 | C4: 962 | D4: 1288 | E4: 775 | F4: 302 | G4: 289
A5: январь 2024 | B5: =SUM(C5:G5) -> 1771 | C5: 406 | D5: 257 | E5: 630 | F5: 257 | G5: 221
A6: февраль 2024 | B6: =SUM(C6:G6) -> 2491 | C6: 457 | D6: 666 | E6: 836 | F6: 387 | G6: 145
A7: март 2024 | B7: =SUM(C7:G7) -> 2894 | C7: 630 | D7: 910 | E7: 717 | F7: 411 | G7: 226
A8: апрель 2024 | B8: =SUM(C8:G8) -> 3277 | C8: 515 | D8: 791 | E8: 1024 | F8: 681 | G8: 266
A9: май, 2024 | B9: =SUM(C9:G9) -> 2081 | C9: 425 | D9: 390 | E9: 694 | F9: 397 | G9: 175
A10: июнь, 2024 | B10: =SUM(C10:G10) -> 2040 | C10: =320*0.8 -> 256 | D10: =661*0.8 -> 528.8 | E10: =739*0.8 -> 591.2 | F10: =509*0.8 -> 407.2 | G10: =321*0.8 -> 256.8
A11: июль, 2024 | B11: 2530 | C11: 752 | D11: =221*0.8 -> 176.8 | E11: =1321*0.8 -> 1056.8 | F11: =147*0.8 -> 117.6 | G11: =89*0.8 -> 71.2
A12: август, 2024 | B12: 1803 | C12: =138*0.8 -> 110.4 | D12: =672*0.8 -> 537.6 | E12: =849*0.8 -> 679.2 | F12: 0 | G12: =144*0.8 -> 115.2
A13: сентябрь, 2024 | B13: 1863 | C13: 417 | D13: 1334 | E13: 130 | F13: 636 | G13: 145
A14: октябрь, 2024 | B14: =SUM(C14:G14) -> 2049 | C14: 519 | D14: 795 | E14: 0 | F14: 525 | G14: 210
A15: ноябрь, 2024 | B15: =SUM(C15:G15) -> 2043 | C15: 495 | D15: 396 | E15: 617 | F15: 359 | G15: 176
A16: декабрь 2024 | B16: =SUM(C16:G16) -> 2649 | C16: 583 | D16: 541 | E16: 437 | F16: 821 | G16: 267
A17: январь, 2025 | B17: =SUM(C17:I17) -> 1716 | C17: 190 | D17: 299 | E17: 559 | F17: 423 | G17: 140 | H17: 89 | I17: 16
A18: февраль 2025 | B18: =SUM(C18:I18) -> 2037 | C18: 252 | D18: 260 | E18: 419 | F18: 377 | G18: 252 | H18: 418 | I18: 59
A19: март, 2025 | B19: =SUM(C19:I19) -> 2966 | C19: 293 | D19: 612 | E19: 708 | F19: 687 | G19: 355 | H19: 195 | I19: 116
A20: апрель, 2025 | B20: =SUM(C20:K20) -> 3100 | C20: 608 | D20: 270 | E20: 832 | F20: 817 | G20: 214 | H20: 43 | I20: 205 | K20: 111
A21: май, 2025 | B21: =SUM(C21:K21) -> 2179 | C21: 435 | D21: 167 | E21: 609 | F21: 445 | G21: 118 | H21: 67 | I21: 180 | K21: 158
A22: июнь, 2025 | B22: =SUM(C22:K22) -> 2161 | C22: 316 | D22: 148 | E22: 552 | F22: 505 | G22: 181 | H22: 220 | I22: 88 | K22: 151
A23: июль, 2025 | B23: 3210 | C23: 69 | D23: 432 | E23: 1411 | F23: 243 | G23: 256 | H23: 456 | I23: 27 | K23: 316
A24: август, 2025 | B24: 2056 | C24: 263 | D24: 70 | E24: 1054 | F24: 0 | G24: 440 | H24: 31 | I24: 26 | K24: 172
A25: сентябрь, 2025 | B25: 3246 | C25: 608 | D25: 398 | E25: 311 | F25: 953 | G25: 347 | H25: 183 | I25: 147 | K25: 299
A26: Октябрь, 2025 | B26: =SUM(C26:K26) -> 2204 | C26: 372 | D26: 324 | E26: 155 | F26: 672 | G26: 260 | H26: 130 | I26: 160 | K26: 131
A27: Ноябрь, 2025 | B27: =SUM(C27:K27) -> 1834 | C27: 210 | D27: 253 | E27: 418 | F27: 543 | G27: 211 | H27: 85 | I27: 54 | K27: 60
A28: Декабрь, 2025 | B28: 3467 | C28: 446 | D28: 167 | E28: 1067 | F28: 978 | G28: 55 | H28: 165 | I28: 144 | K28: 445
A29: Январь, 2026 | B29: 1908 | C29: 283 | D29: 94 | E29: 1068 | F29: 603 | G29: 168 | H29: 171 | I29: 143 | K29: 196
A30: Февраль, 2026 | B30: =SUM(C30:K30) -> 1694 | C30: 212 | D30: 121 | E30: 452 | F30: 371 | G30: 174 | H30: 96 | I30: 89 | K30: 179
A31: Март, 2026 | B31: 1310 | C31: 282 | D31: 153 | E31: 479 | F31: 356 | G31: 137 | H31: 244 | I31: 28 | K31: 192
A32: Апрель, 2026 | B32: =SUM(C32:K32) -> 2269 | C32: 198 | D32: 214 | E32: 583 | F32: 645 | G32: 194 | H32: 186 | I32: 84 | K32: 165
A33: Май, 2026 | B33: =SUM(C33:K33) -> 1554 | C33: 188 | D33: 166 | E33: 358 | F33: 293 | G33: 197 | H33: 128 | I33: 76 | K33: 148
A34: Июнь, 2026 | B34: =SUM(C34:K34) -> 1203 | C34: 173 | D34: 87 | E34: 7 | F34: 520 | G34: 130 | H34: 154 | I34: 101 | K34: 31
A35: Июль, 2026 | B35: =SUM(C35:K35) -> 2350 | C35: 354 | D35: 99 | E35: 501 | F35: 431 | G35: 448 | H35: 180 | I35: 171 | J35: 134 | K35: 32
A36: Август, 2026 | B36: =SUM(C36:K36) -> 2209 | C36: 49 | D36: 803 | E36: 677 | F36: 46 | G36: 122 | H36: 45 | I36: 69 | J36: 192 | K36: 206
A37: Исполнитель | B37: Текущие задачи | K37: Работа с заявками
A38: Сапогов | B38: 1. Проводилась подготовка ТЗ на выполнение работ по интеграции с РСЭД Тезис 2. Организация и взаимодействие с участниками и техподдержкой по настройке и тестировании кроссподписания. 3. Проверка мероприятий предварительных ПИ на 2027 год среди МО и департамента здравоохранения. 4. Проводилась работа по администрированию, настройке прав, технической поддержке и решения иных вопросов на период отсутствия Чечеткина М.И., Обмоловой В.В. Рогановой А.И. 5. Подготовлены критерии для отчета по отслеживанию динамики авторизации через ЕСИА, сформулированы требования для отчета по командировкам и отпускам (заявки), решены несколько вопросов по ошибкам при импорте данных УКТ-Услуга, направлен отзыв заявки на регистрацию программы для ЭВМ (ИИ) чтобы повторно не платить пошлину. 6. Направлены ежемесячные отчеты по аудиту ПО и импортзамещению в ДИТиС (через депфин) | J38: Исполнено резолюций - 13, направлено заявок в службу технической поддержки - 24 (Смета)
A39: Кошик | B39: Сбор статистики по муниципалитетам - использования интеграции по направлениям: МИР, ПП, ЭДО, СФР, Имущество и т.п. | J39: Направлено заявок в службу технической поддержки - 2
A40: Худышкин | B40: Работа Техфоргосом, Мароп и Аппаратом Губернатора для утверждения и построения рабочего процесса (консолидация информации всеми сторонами) интеграции с ЕСКУ. Восстановление подключений Imon ГКУ.drx . Поддержка и администрирование ИОГВ с 04.08.2026 по 12.08.2026. Поддержка, администрирование и консультация по ГИС АПК и Астралу. Работа по организации интеграции ГИС ЕСКУ и ГИС Сметы. Оповещеие учреждений о сопостовлении справочников, консультация. Взаимодействие с представителями подрядчиков (Мароп, Хендисофт, Аппарат Губернатора) для согласования и реализации доработок по интеграции. Взаимодействие с представителями подрядчиков (Fargos, Krista) по централизации Сметы в рабочих чатах Мах и по телефону. Консультация / тех. поддержка / маршрутизация заявок муниципалитетов в части подключения и настройки централизованной Сметы ЯНАО. Поддержка по настройкам ГИС ГМП, ГИС Имущество, перечеисление на карты МИР в базах муниципалитетов. Работы с базами муниципалитетов. Курирование работы функционала интеграции ГИС ЕСКУ и Сметы в ЦБ ОГВ ЯНАО. | J40: Направлено заявок в службу технической поддержки - 13
...
